# 6.2 Iterando para um Novo Design da Aplicação

O processo para evoluir uma aplicação é trablhso e deve ser feito de forma incremental. As vezes dá aquele desejo de sairmos modificando tudo o quanto antes mas, nessas horas temos que nos conter e planejar as ações a serem tomadas. Não há necessidade de alterarmos todo o projeto e arquitetura da  aplicação de uma única vez.

Considerando nossa lista de tarefas apresentada no início do capítulo, o Tese Funcional, evido a falha apresentada, sugere que devemos iniciar pelo segundo item, ou seja, oferecer URLs únicos para cada lista.

Para dar início a mudança, precisamos alterar nosso teste unitário para refletir o que desejamos. O teste alterado fica conforme abaixo:

Alteremos o método `test_redirects_after_POST` para que, o redirecionamento seja para outra URL, diferente de `'/'`. No caso, usamos a URL `/lists/the-only-list-in-the-world/`.  \(linhas 26 a 30\)

```text
from django.urls import resolve
from django.test import TestCase
from lists.views import home_page

class HomePageTest(TestCase):

	def test_root_url_resolves_to_home_page_view(self):
		found = resolve('/')
		self.assertEquals(found.func, home_page)

	def test_home_page_returns_correct_html(self):
		response = self.client.get('/')
		self.assertTemplateUsed(response, 'home.html')

	def test_only_saves_items_when_necessary(self):
		self.client.get('/')
		self.assertEquals(Item.objects.count(), 0)

	def test_can_save_a_POST_request(self):
		self.client.post('/', data={'item_text': 'A new list item'})

		self.assertEquals(Item.objects.count(), 1)
		new_item = Item.objects.first()
		self.assertEquals(new_item.text, 'A new list item')

	def test_redirects_after_POST(self):
		response = self.client.post('/', data={'item_text': 'A new list item'})

		self.assertEquals(response.status_code, 302)
		self.assertEquals(response['location'], '/lists/the-only-list-in-the-world/')

	def test_displays_all_list_itens(self):
		Item.objects.create(text='itemey 1')
		Item.objects.create(text='itemey 2')

		response = self.client.get('/')

		self.assertIn('itemey 1', response.content.decode())
		self.assertIn('itemey 2', response.content.decode())


from lists.models import Item

class ItemModelTest(TestCase):

	def test_saving_and_retriving_items(self):
		first_item = Item()
		first_item.text = 'The first (ever) list item'
		first_item.save()

		second_item = Item()
		second_item.text = 'Item the second'
		second_item.save()

		saved_items = Item.objects.all()
		self.assertEquals(saved_items.count(),2)

		first_saved_item = saved_items[0]
		second_saved_item = saved_items[1]

		self.assertEquals(first_saved_item.text, 'The first (ever) list item')
		self.assertEquals(second_saved_item.text, 'Item the second')

```

Ao executar esse teste obtemos o resultado abaixo:

```text
(superlists) auri@av:~/insync/tdd/superlists/superlists$ python manage.py test
Creating test database for alias 'default'...
System check identified no issues (0 silenced).
........F
======================================================================
FAIL: test_multiple_users_can_start_lists_at_different_urls (functional_tests.tests.NewVsitorTest)
----------------------------------------------------------------------
Traceback (most recent call last):
  File "/home/auri/insync/tdd/superlists/superlists/functional_tests/tests.py", line 98, in test_multiple_users_can_start_lists_at_different_urls
    self.assertRegex(edith_list_url, '/list/.+')
AssertionError: Regex didn't match: '/list/.+' not found in 'http://localhost:41549/'

----------------------------------------------------------------------
Ran 9 tests in 8.597s

FAILED (failures=1)
Destroying test database for alias 'default'...
```

Para corrigir o problemas precisamos editar nossa função de view conforme abaixo \(linha 8\):

```text
from django.shortcuts import redirect, render
from lists.models import Item

# Create your views here.
def home_page(request):
	if request.method == 'POST':
		Item.objects.create(text=request.POST['item_text'])
		return redirect('/lists/the-only-list-in-the-world/')

	items = Item.objects.all()
	return render(request, 'home.html', {'items': items})
```

Fica claro que essa alteração fará outros testes falharem, conforme abaixo:

```text
(superlists) auri@av:~/insync/tdd/superlists/superlists$ python manage.py test
Creating test database for alias 'default'...
System check identified no issues (0 silenced).
....F..EE
======================================================================
ERROR: test_can_start_a_list_for_one_user (functional_tests.tests.NewVsitorTest)
----------------------------------------------------------------------
Traceback (most recent call last):
...
selenium.common.exceptions.NoSuchElementException: Message: Unable to locate element: [id="id_list_table"]


======================================================================
ERROR: test_multiple_users_can_start_lists_at_different_urls (functional_tests.tests.NewVsitorTest)
----------------------------------------------------------------------
Traceback (most recent call last):
...
selenium.common.exceptions.InvalidSessionIdException: Message: Tried to run command without establishing a connection


======================================================================
FAIL: test_redirects_after_POST (lists.tests.HomePageTest)
----------------------------------------------------------------------
Traceback (most recent call last):
  File "/home/auri/insync/tdd/superlists/superlists/lists/tests.py", line 30, in test_redirects_after_POST
    self.assertEquals(response['location'], '/')
AssertionError: '/lists/the-only-list-in-the-world/' != '/'
- /lists/the-only-list-in-the-world/
+ /


----------------------------------------------------------------------
Ran 9 tests in 26.207s

FAILED (failures=1, errors=2)
Destroying test database for alias 'default'...
```

Isso que provocamos é chamado de regressão, ou seja, não apenas o teste inicial esta falhando, mas outros passaram a falhar.

Para continuar, inicialmente vamos escrever um novo teste unitário para avaliar o retorno nessa nova URL. O arquivo `lists/tests.py` passará a ter o seguinte conteúdo. Observa-se que uma nova classe de teste foi adicionada no arquivo \(`ListViewTest`\) com um método de teste denominado `test_display_all_items`.

```text
from django.urls import resolve
from django.test import TestCase
from lists.views import home_page

class HomePageTest(TestCase):

	def test_root_url_resolves_to_home_page_view(self):
		found = resolve('/')
		self.assertEquals(found.func, home_page)

	def test_home_page_returns_correct_html(self):
		response = self.client.get('/')
		self.assertTemplateUsed(response, 'home.html')

	def test_only_saves_items_when_necessary(self):
		self.client.get('/')
		self.assertEquals(Item.objects.count(), 0)

	def test_can_save_a_POST_request(self):
		self.client.post('/', data={'item_text': 'A new list item'})

		self.assertEquals(Item.objects.count(), 1)
		new_item = Item.objects.first()
		self.assertEquals(new_item.text, 'A new list item')

	def test_redirects_after_POST(self):
		response = self.client.post('/', data={'item_text': 'A new list item'})

		self.assertEquals(response.status_code, 302)
		self.assertEquals(response['location'], '/lists/the-only-list-in-the-world/')

	def test_displays_all_list_itens(self):
		Item.objects.create(text='itemey 1')
		Item.objects.create(text='itemey 2')

		response = self.client.get('/')

		self.assertIn('itemey 1', response.content.decode())
		self.assertIn('itemey 2', response.content.decode())



class ListViewTest(TestCase):
	def test_displays_all_list_itens(self):
		Item.objects.create(text='itemey 1')
		Item.objects.create(text='itemey 2')

		response = self.client.get('/lists/the-only-list-in-the-world/')

		self.assertContains(response, 'itemey 1')
		self.assertContains(response, 'itemey 2')



from lists.models import Item

class ItemModelTest(TestCase):

	def test_saving_and_retriving_items(self):
		first_item = Item()
		first_item.text = 'The first (ever) list item'
		first_item.save()

		second_item = Item()
		second_item.text = 'Item the second'
		second_item.save()

		saved_items = Item.objects.all()
		self.assertEquals(saved_items.count(),2)

		first_saved_item = saved_items[0]
		second_saved_item = saved_items[1]

		self.assertEquals(first_saved_item.text, 'The first (ever) list item')
		self.assertEquals(second_saved_item.text, 'Item the second')

```

Com a execução desses testes, obtemos um erro 404 pois a URL ainda não existe.

```text
(superlists) auri@av:~/insync/tdd/superlists/superlists$ python manage.py test
Creating test database for alias 'default'...
System check identified no issues (0 silenced).
.......FEE
======================================================================
ERROR: test_can_start_a_list_for_one_user (functional_tests.tests.NewVsitorTest)
----------------------------------------------------------------------
Traceback (most recent call last):
...
selenium.common.exceptions.InvalidSessionIdException: Message: Tried to run command without establishing a connection


======================================================================
ERROR: test_multiple_users_can_start_lists_at_different_urls (functional_tests.tests.NewVsitorTest)
----------------------------------------------------------------------
Traceback (most recent call last):
...
selenium.common.exceptions.InvalidSessionIdException: Message: Tried to run command without establishing a connection


======================================================================
FAIL: test_displays_all_list_itens (lists.tests.ListViewTest)
----------------------------------------------------------------------
...
    self.assertEqual(
AssertionError: 404 != 200 : Couldn't retrieve content: Response code was 404 (expected 200)

----------------------------------------------------------------------
Ran 10 tests in 27.122s

FAILED (failures=1, errors=2)
Destroying test database for alias 'default'...
```

A correção 

